Workbook

Sheet Dashboard
G1: General Notes
B2: Total Revenue Projected Monthly | C2: =C6/12 -> 145522 | G2: Revenue Projections are based on rental income only
B3: Total Expenses Projected Monthly | C3: =C7/12 -> 123550 | G3: Expenses include (Taxes, Insurance, Mortgage Interest, Management, Utilities, R&M, Turns)
B4: Total Net Income Projected Monthly | C4: =C8/12 -> 21972 | G4: Vacancy is pre-factored into revenue projections
G5: Building Improvement Expenses Tagged on far right not in monthly expense actual figure
B6: Total Revenue Projected Annual | C6: =sum('Lancaster Hotel'!I75,'Concord Manor Apts'!I75,'Bavarian Village'!I75,'Glasstown Holdings'!I75,'Rain Tree Apts'!I75,'RDE Central'!I75,ENPH!I75,'RD Sidney'!I75,'New Lex MHP'!I75) -> 1746264 | G6: MT Vernon Not Calculated in Dashboard
B7: Total Expenses Projected Annual | C7: =sum('Lancaster Hotel'!M75,'Concord Manor Apts'!M75,'Bavarian Village'!M75,'Glasstown Holdings'!M75,'Rain Tree Apts'!M75,'RDE Central'!M75,ENPH!M75,'RD Sidney'!M75,'New Lex MHP'!I75) -> 1482600 | G7: Cap Ex & Prop. Stab. staring in June is on the far right column but not factored into expenses.
B8: Total Net Income Projected Annual | C8: =C6-C7 -> 263664
B10: January
B11: Monthly Revenue | C11: =sum('Lancaster Hotel'!H15,'Concord Manor Apts'!H15,'Bavarian Village'!H15,'Glasstown Holdings'!H15,'Rain Tree Apts'!H15,'RDE Central'!H15,ENPH!H15,'RD Sidney'!H15,'New Lex MHP'!H15) -> 136059
B12: Monthly Expenses | C12: =sum('Lancaster Hotel'!L15,'Concord Manor Apts'!L15,'Bavarian Village'!L15,'Glasstown Holdings'!L15,'Rain Tree Apts'!L15,'RDE Central'!L15,ENPH!L15,'RD Sidney'!L15,'New Lex MHP'!L15) -> 136807
B13: Monthly Net Income | C13: =C11-C12 -> -748
B15: February
B16: Monthly Revenue | C16: =sum('Lancaster Hotel'!H20,'Concord Manor Apts'!L20,'Bavarian Village'!H20,'Glasstown Holdings'!L20,'Rain Tree Apts'!L20,'RDE Central'!L20,ENPH!L20,'RD Sidney'!H20,'New Lex MHP'!L20) -> 149324
B17: Monthly Expenses | C17: =sum('Lancaster Hotel'!L20,'Concord Manor Apts'!L20,'Bavarian Village'!L20,'Glasstown Holdings'!L20,'Rain Tree Apts'!L20,'RDE Central'!L20,ENPH!L20,'RD Sidney'!L20,'New Lex MHP'!L20) -> 119716
B18: Monthly Net Income | C18: =C16-C17 -> 29608
B20: March
B21: Monthly Revenue | C21: =sum('Lancaster Hotel'!H26,'Concord Manor Apts'!H26,'Bavarian Village'!H26,'Glasstown Holdings'!H26,'Rain Tree Apts'!H26,'RDE Central'!H26,ENPH!H26,'RD Sidney'!H26,'New Lex MHP'!H26) -> 137959
B22: Monthly Expenses | C22: =sum('Lancaster Hotel'!L26,'Concord Manor Apts'!L26,'Bavarian Village'!L26,'Glasstown Holdings'!L26,'Rain Tree Apts'!L26,'RDE Central'!L26,ENPH!L26,'RD Sidney'!L26,'New Lex MHP'!L26) -> 170556
B23: Monthly Net Income | C23: =C21-C22 -> -32597
B25: April
B26: Monthly Revenue | C26: =sum('Lancaster Hotel'!H31,'Concord Manor Apts'!H31,'Bavarian Village'!H31,'Glasstown Holdings'!H31,'Rain Tree Apts'!H31,'RDE Central'!H31,ENPH!H31,'RD Sidney'!H31,'New Lex MHP'!H31,'TRS Portfolio'!H31) -> 156446
B27: Monthly Expenses | C27: =sum('Lancaster Hotel'!L36,'Concord Manor Apts'!L31,'Bavarian Village'!L31,'Glasstown Holdings'!L31,'Rain Tree Apts'!L31,'RDE Central'!L31,ENPH!L31,'RD Sidney'!L31,'New Lex MHP'!L31,'TRS Portfolio'!L31) -> 175922
B28: Monthly Net Income | C28: =C26-C27 -> -19476
B30: May
B31: Monthly Revenue | C31: =sum('Lancaster Hotel'!H36,'Concord Manor Apts'!H36,'Bavarian Village'!H36,'Glasstown Holdings'!H36,'Rain Tree Apts'!H36,'RDE Central'!H36,ENPH!H36,'RD Sidney'!H36,'New Lex MHP'!H36,'TRS Portfolio'!H36,'MT Vernon Studios'!H36) -> 193775
B32: Monthly Expenses | C32: =sum('Lancaster Hotel'!L36,'Bavarian Village'!L36,'Glasstown Holdings'!L36,'Rain Tree Apts'!L36,'RDE Central'!L36,ENPH!L36,'RD Sidney'!L36,'New Lex MHP'!L36,'TRS Portfolio'!L36,'MT Vernon Studios'!L36) -> 130236
B33: Monthly Net Income | C33: =C31-C32 -> 63539
B35: June
B36: Monthly Revenue
B37: Monthly Expenses
B38: Monthly Net Income | C38: =C36-C37 -> 0
B40: July
B41: Monthly Revenue
B42: Monthly Expenses
B43: Monthly Net Income
B45: August
B46: Monthly Revenue
B47: Monthly Expenses
B48: Monthly Net Income
...

Sheet Lancaster Hotel
A1: KEY
A2: Manual Input
A3: Owner Input or Formula
A4: Formula
B5: # of Units | C5: 24 | I5: KPI Tracker
A10: Week Ending Sunday | B10: # of Occupied Units | C10: Occupancy % | D10: Total Leased Rent Amount $ | E10: Average Rent | F10: Total Collections to Date $ | G10: Collection Percentage | H10: Actual Revenue (Monthly Only) | I10: Budgeted Revenue (Monthly Only) | J10: Variance $ | K10: Variance % | L10: Actual Expense (Monthly Only) | M10: Budgeted Expense (Monthly Only | N10: Variance $ | O10: Variance % | P10: Net Income | Q10: Net Income Budgeteted | R10: Total Expenses
A11: 45662 | B11: 19 | C11: =IF(B11=0,"",B11/C$5) -> 0.79166667 | D11: 24845 | E11: =IFERROR(D11/B11,"") -> 1307.6316 | F11: 24030 | G11: =IFERROR(F11/D11,"") -> 0.96719662 | R11: 123 N Broad Street, Lancaster, Ohio 43130
A12: =A11+7 -> 45669 | B12: 19 | C12: =IF(B12=0,"",B12/C$5) -> 0.79166667 | D12: 24845 | E12: =IFERROR(D12/B12,"") -> 1307.6316 | F12: 24845 | G12: =IFERROR(F12/D12,"") -> 1
A13: =A12+7 -> 45676 | B13: 20 | C13: =IF(B13=0,"",B13/C$5) -> 0.83333333 | D13: 25895 | E13: =IFERROR(D13/B13,"") -> 1294.75 | F13: 25488 | G13: =IFERROR(F13/D13,"") -> 0.98428268
A14: =A13+7 -> 45683 | B14: 20 | C14: =IF(B14=0,"",B14/C$5) -> 0.83333333 | D14: 25895 | E14: =IFERROR(D14/B14,"") -> 1294.75 | F14: 25488 | G14: =IFERROR(F14/D14,"") -> 0.98428268
A15: Monthly Target | B15: 23 | C15: =IF(B15=0,"",B15/C$5) -> 0.95833333 | D15: 33500 | E15: =D15/B15 -> 1456.5217 | F15: 33500 | G15: =IFERROR(F15/D15,"") -> 1 | H15: 25488 | I15: 33500 | J15: =IF(H15=0,"",H15-I15) -> -8012 | K15: =IFERROR((H15-I15)/H15,"") -> -0.314344 | L15: 36130 | M15: 29500 | N15: =IF(L15=0,"",L15-M15) -> 6630 | O15: =IFERROR((L15-M15)/L15,"") -> 0.18350401 | P15: =H15-L15 -> -10642 | Q15: =I15-M15 -> 4000 | R15: Dual Lease Option Expense paid on the 29th of January
A16: =A14+7 -> 45690 | B16: 20 | C16: =IF(B16=0,"",B16/C$5) -> 0.83333333 | D16: 25895 | E16: =IFERROR(D16/B16,"") -> 1294.75 | F16: 25895 | G16: =IFERROR(F16/D16,"") -> 1
A17: =A16+7 -> 45697 | B17: 21 | C17: =IF(B17=0,"",B17/C$5) -> 0.875 | D17: 27945 | E17: =IFERROR(D17/B17,"") -> 1330.7143 | F17: 27695 | G17: =IFERROR(F17/D17,"") -> 0.99105386
A18: =A17+7 -> 45704 | B18: 21 | C18: =IF(B18=0,"",B18/C$5) -> 0.875 | D18: 27945 | E18: =IFERROR(D18/B18,"") -> 1330.7143 | F18: 27695 | G18: =IFERROR(F18/D18,"") -> 0.99105386
A19: =A18+7 -> 45711 | B19: 21 | C19: =IF(B19=0,"",B19/C$5) -> 0.875 | D19: 27945 | E19: =IFERROR(D19/B19,"") -> 1330.7143 | F19: 27695 | G19: =IFERROR(F19/D19,"") -> 0.99105386
A20: Monthly Target | B20: 23 | C20: =IF(B20=0,"",B20/C$5) -> 0.95833333 | D20: 33500 | E20: =D20/B20 -> 1456.5217 | F20: 33500 | G20: =IFERROR(F20/D20,"") -> 1 | H20: 27348 | I20: 33500 | J20: =IF(H20=0,"",H20-I20) -> -6152 | K20: =IFERROR((H20-I20)/H20,"") -> -0.22495246 | L20: 13155 | M20: 29500 | N20: =IF(L20=0,"",L20-M20) -> -16345 | O20: =IFERROR((L20-M20)/L20,"") -> -1.2424933 | P20: =H20-L20 -> 14193 | Q20: =I20-M20 -> 4000 | R20: $3500 in Building imrpovements NOT included in expenses
A21: =A19+7 -> 45718 | B21: 21 | C21: =IF(B21=0,"",B21/C$5) -> 0.875 | D21: 28150 | E21: =IFERROR(D21/B21,"") -> 1340.4762 | F21: 15530 | G21: =IFERROR(F21/D21,"") -> 0.55168739
A22: =A21+7 -> 45725 | B22: 21 | C22: =IF(B22=0,"",B22/C$5) -> 0.875 | D22: 28150 | E22: =IFERROR(D22/B22,"") -> 1340.4762 | F22: 27343 | G22: =IFERROR(F22/D22,"") -> 0.97133215
A23: =A22+7 -> 45732 | B23: 21 | C23: =IF(B23=0,"",B23/C$5) -> 0.875 | D23: 28150 | E23: =IFERROR(D23/B23,"") -> 1340.4762 | F23: 27343 | G23: =IFERROR(F23/D23,"") -> 0.97133215
A24: =A23+7 -> 45739 | B24: 21 | C24: =IF(B24=0,"",B24/C$5) -> 0.875 | D24: 28150 | E24: =IFERROR(D24/B24,"") -> 1340.4762 | F24: 27343 | G24: =IFERROR(F24/D24,"") -> 0.97133215
A25: =A24+7 -> 45746 | B25: 20 | C25: =IF(B25=0,"",B25/C$5) -> 0.83333333 | D25: 27350 | E25: =IFERROR(D25/B25,"") -> 1367.5 | F25: 27343 | G25: =IFERROR(F25/D25,"") -> 0.99974406
A26: Monthly Target | B26: 23 | C26: =IF(B26=0,"",B26/C$5) -> 0.95833333 | D26: 33500 | E26: =D26/B26 -> 1456.5217 | F26: 33500 | G26: =IFERROR(F26/D26,"") -> 1 | H26: 27343 | I26: 33500 | J26: =IF(H26=0,"",H26-I26) -> -6157 | K26: =IFERROR((H26-I26)/H26,"") -> -0.22517646 | L26: 33780 | M26: 29500 | N26: =IF(L26=0,"",L26-M26) -> 4280 | O26: =IFERROR((L26-M26)/L26,"") -> 0.12670219 | P26: =H26-L26 -> -6437 | Q26: =I26-M26 -> 4000 | R26: $1,060 building improvements and 6 months proeprty taxes
A27: =A25+7 -> 45753 | B27: 19 | C27: =IF(B27=0,"",B27/C$5) -> 0.79166667 | D27: 26630 | E27: =IFERROR(D27/B27,"") -> 1401.5789 | F27: 26630 | G27: =IFERROR(F27/D27,"") -> 1
A28: =A27+7 -> 45760 | B28: 19 | C28: =IF(B28=0,"",B28/C$5) -> 0.79166667 | D28: 26630 | E28: =IFERROR(D28/B28,"") -> 1401.5789 | F28: 26630 | G28: =IFERROR(F28/D28,"") -> 1
A29: =A28+7 -> 45767 | B29: 21 | C29: =IF(B29=0,"",B29/C$5) -> 0.875 | D29: 29230 | E29: =IFERROR(D29/B29,"") -> 1391.9048 | F29: 27215 | G29: =IFERROR(F29/D29,"") -> 0.93106398
A30: =A29+7 -> 45774 | B30: 21 | C30: =IF(B30=0,"",B30/C$5) -> 0.875 | D30: 29230 | E30: =IFERROR(D30/B30,"") -> 1391.9048 | F30: 27757 | G30: =IFERROR(F30/D30,"") -> 0.94960657
A31: Monthly Target | B31: 23 | C31: =IF(B31=0,"",B31/C$5) -> 0.95833333 | D31: 33500 | E31: =D31/B31 -> 1456.5217 | F31: 33500 | G31: =IFERROR(F31/D31,"") -> 1 | H31: 34355 | I31: 33500 | J31: =IF(H31=0,"",H31-I31) -> 855 | K31: =IFERROR((H31-I31)/H31,"") -> 0.024887207 | L31: 29115 | M31: 29500 | N31: =IF(L31=0,"",L31-M31) -> -385 | O31: =IFERROR((L31-M31)/L31,"") -> -0.013223424 | P31: =H31-L31 -> 5240 | Q31: =I31-M31 -> 4000 | R31: $7,300 in Building Improvements (Lowes Materials for Unit Turns)
A32: =A30+7 -> 45781 | B32: 21 | C32: =IF(B32=0,"",B32/C$5) -> 0.875 | D32: 29230 | E32: =IFERROR(D32/B32,"") -> 1391.9048 | F32: 27980 | G32: =IFERROR(F32/D32,"") -> 0.95723572
A33: =A32+7 -> 45788 | B33: 21 | C33: =IF(B33=0,"",B33/C$5) -> 0.875 | D33: 29230 | E33: =IFERROR(D33/B33,"") -> 1391.9048 | F33: 29230 | G33: =IFERROR(F33/D33,"") -> 1
A34: =A33+7 -> 45795 | B34: 21 | C34: =IF(B34=0,"",B34/C$5) -> 0.875 | D34: 29230 | E34: =IFERROR(D34/B34,"") -> 1391.9048 | F34: 29230 | G34: =IFERROR(F34/D34,"") -> 1
A35: =A34+7 -> 45802 | B35: 21 | C35: =IF(B35=0,"",B35/C$5) -> 0.875 | D35: 29230 | E35: =IFERROR(D35/B35,"") -> 1391.9048 | F35: 29230 | G35: =IFERROR(F35/D35,"") -> 1
A36: Monthly Target | B36: 23 | C36: =IF(B36=0,"",B36/C$5) -> 0.95833333 | D36: 33500 | E36: =D36/B36 -> 1456.5217 | F36: 33500 | G36: =IFERROR(F36/D36,"") -> 1 | H36: 26055 | I36: 33500 | J36: =IF(H36=0,"",H36-I36) -> -7445 | K36: =IFERROR((H36-I36)/H36,"") -> -0.2857417 | L36: 25161 | M36: 29500 | N36: =IF(L36=0,"",L36-M36) -> -4339 | O36: =IFERROR((L36-M36)/L36,"") -> -0.17244943 | P36: =H36-L36 -> 894 | Q36: =I36-M36 -> 4000 | R36: $1000 additional in building improvements
A37: =A35+7 -> 45809 | B37: 19 | C37: =IF(B37=0,"",B37/C$5) -> 0.79166667 | D37: 27285 | E37: =IFERROR(D37/B37,"") -> 1436.0526 | F37: 20090 | G37: =IFERROR(F37/D37,"") -> 0.736302
A38: =A37+7 -> 45816 | B38: 19 | C38: =IF(B38=0,"",B38/C$5) -> 0.79166667 | D38: 27285 | E38: =IFERROR(D38/B38,"") -> 1436.0526 | F38: 27285 | G38: =IFERROR(F38/D38,"") -> 1
A39: =A38+7 -> 45823 | B39: 19 | C39: =IF(B39=0,"",B39/C$5) -> 0.79166667 | D39: 27285 | E39: =IFERROR(D39/B39,"") -> 1436.0526 | F39: 27285 | G39: =IFERROR(F39/D39,"") -> 1
A40: =A39+7 -> 45830 | B40: 19 | C40: =IF(B40=0,"",B40/C$5) -> 0.79166667 | D40: 27285 | E40: =IFERROR(D40/B40,"") -> 1436.0526 | F40: 27285 | G40: =IFERROR(F40/D40,"") -> 1
A41: =A40+7 -> 45837 | B41: 19 | C41: =IF(B41=0,"",B41/C$5) -> 0.79166667 | D41: 27285 | E41: =IFERROR(D41/B41,"") -> 1436.0526 | F41: 27285 | G41: =IFERROR(F41/D41,"") -> 1
A42: Monthly Target | B42: 23 | C42: =IF(B42=0,"",B42/C$5) -> 0.95833333 | D42: 33500 | E42: =D42/B42 -> 1456.5217 | F42: 33500 | G42: =IFERROR(F42/D42,"") -> 1 | H42: 26698 | I42: 33500 | J42: =IF(H42=0,"",H42-I42) -> -6802 | K42: =IFERROR((H42-I42)/H42,"") -> -0.25477564 | L42: 25727 | M42: 29500 | N42: =IF(L42=0,"",L42-M42) -> -3773 | O42: =IFERROR((L42-M42)/L42,"") -> -0.14665526 | P42: =H42-L42 -> 971 | Q42: =I42-M42 -> 4000
A43: =A41+7 -> 45844 | B43: 19 | C43: =IF(B43=0,"",B43/C$5) -> 0.79166667 | D43: 27490 | E43: =IFERROR(D43/B43,"") -> 1446.8421 | F43: 27490 | G43: =IFERROR(F43/D43,"") -> 1
A44: =A43+7 -> 45851 | B44: 20 | C44: =IF(B44=0,"",B44/C$5) -> 0.83333333 | D44: 28840 | E44: =IFERROR(D44/B44,"") -> 1442 | F44: 27490 | G44: =IFERROR(F44/D44,"") -> 0.95319001
...

Sheet Concord Manor Apts
A1: KEY
A2: Manual Input
A3: Owner Input or Formula
A4: Formula | B4: Concord Manor Apartments
B5: # of Units | C5: 35 | I5: KPI Tracker
A10: Week Ending Sunday | B10: # of Occupied Units | C10: Occupancy % | D10: Total Leased Rent Amount $ | E10: Average Rent | F10: Total Collections to Date $ | G10: Collection Percentage | H10: Actual Revenue (Monthly Only) | I10: Budgeted Revenue (Monthly Only) | J10: Variance $ | K10: Variance % | L10: Actual Expense (Monthly Only) | M10: Budgeted Expense (Monthly Only | N10: Variance $ | O10: Variance % | P10: Net Income | Q10: Net Income Budgeted | R10: Notes:
A11: 45662 | B11: 34 | C11: =IF(B11=0,"",B11/C$5) -> 0.97142857 | D11: 28175 | E11: =IFERROR(D11/B11,"") -> 828.67647 | F11: 24688 | G11: =IFERROR(F11/D11,"") -> 0.8762378 | R11: 123 & 129 W Walnut Street, Lancaster, Ohio 43130
A12: =A11+7 -> 45669 | B12: 33 | C12: =IF(B12=0,"",B12/C$5) -> 0.94285714 | D12: 27400 | E12: =IFERROR(D12/B12,"") -> 830.30303 | F12: 27825 | G12: =IFERROR(F12/D12,"") -> 1.0155109
A13: =A12+7 -> 45676 | B13: 33 | C13: =IF(B13=0,"",B13/C$5) -> 0.94285714 | D13: 27400 | E13: =IFERROR(D13/B13,"") -> 830.30303 | F13: 28275 | G13: =IFERROR(F13/D13,"") -> 1.0319343
A14: =A13+7 -> 45683 | B14: 34 | C14: =IF(B14=0,"",B14/C$5) -> 0.97142857 | D14: 28400 | E14: =IFERROR(D14/B14,"") -> 835.29412 | F14: 28597 | G14: =IFERROR(F14/D14,"") -> 1.0069366
A15: Monthly Target | B15: 33 | C15: =IF(B15=0,"",B15/C$5) -> 0.94285714 | D15: 28500 | E15: =D15/B15 -> 863.63636 | F15: 28500 | G15: =IFERROR(F15/D15,"") -> 1 | H15: 28597 | I15: 28500 | J15: =IF(H15=0,"",H15-I15) -> 97 | K15: =IFERROR((H15-I15)/H15,"") -> 0.0033919642 | L15: 26662 | M15: 23100 | N15: =IF(L15=0,"",L15-M15) -> 3562 | O15: =IFERROR((L15-M15)/L15,"") -> 0.13359838 | P15: =H15-L15 -> 1935 | Q15: =I15-M15 -> 5400
A16: =A14+7 -> 45690 | B16: 34 | C16: =IF(B16=0,"",B16/C$5) -> 0.97142857 | D16: 28400 | E16: =D16/B16 -> 835.29412 | F16: 28597 | G16: =IFERROR(F16/D16,"") -> 1.0069366
A17: =A16+7 -> 45697 | B17: 34 | C17: =IF(B17=0,"",B17/C$5) -> 0.97142857 | D17: 28400 | E17: =D17/B17 -> 835.29412 | F17: 25809 | G17: =IFERROR(F17/D17,"") -> 0.90876761
A18: =A17+7 -> 45704 | B18: 34 | C18: =IF(B18=0,"",B18/C$5) -> 0.97142857 | D18: 28400 | E18: =D18/B18 -> 835.29412 | F18: 26881 | G18: =IFERROR(F18/D18,"") -> 0.94651408
A19: =A18+7 -> 45711 | B19: 34 | C19: =IF(B19=0,"",B19/C$5) -> 0.97142857 | D19: 28400 | E19: =D19/B19 -> 835.29412 | F19: 28063 | G19: =IFERROR(F19/D19,"") -> 0.9881338
A20: Monthly Target | B20: 33 | C20: =IF(B20=0,"",B20/C$5) -> 0.94285714 | D20: 28500 | E20: =D20/B20 -> 863.63636 | F20: 28500 | G20: =IFERROR(F20/D20,"") -> 1 | H20: 29178 | I20: 28500 | J20: =IF(H20=0,"",H20-I20) -> 678 | K20: =IFERROR((H20-I20)/H20,"") -> 0.023236685 | L20: 26814 | M20: 23100 | N20: =IF(L20=0,"",L20-M20) -> 3714 | O20: =IFERROR((L20-M20)/L20,"") -> 0.13850973 | P20: =H20-L20 -> 2364 | Q20: =I20-M20 -> 5400 | R20: $23,125 in building improvements not included in expenses
A21: =A19+7 -> 45718 | B21: 35 | C21: =IF(B21=0,"",B21/C$5) -> 1 | D21: 29400 | E21: =D21/B21 -> 840 | F21: 14427 | G21: =IFERROR(F21/D21,"") -> 0.49071429
A22: =A21+7 -> 45725 | B22: 35 | C22: =IF(B22=0,"",B22/C$5) -> 1 | D22: 29400 | E22: =D22/B22 -> 840 | F22: 28106 | G22: =IFERROR(F22/D22,"") -> 0.95598639
A23: =A22+7 -> 45732 | B23: 35 | C23: =IF(B23=0,"",B23/C$5) -> 1 | D23: 29400 | E23: =D23/B23 -> 840 | F23: 28676 | G23: =IFERROR(F23/D23,"") -> 0.97537415
A24: =A23+7 -> 45739 | B24: 34 | C24: =IF(B24=0,"",B24/C$5) -> 0.97142857 | D24: 28550 | E24: =D24/B24 -> 839.70588 | F24: 29269 | G24: =IFERROR(F24/D24,"") -> 1.0251839
A25: =A24+7 -> 45746 | B25: 34 | C25: =IF(B25=0,"",B25/C$5) -> 0.97142857 | D25: 28550 | E25: =D25/B25 -> 839.70588 | F25: 29269 | G25: =IFERROR(F25/D25,"") -> 1.0251839
A26: Monthly Target | B26: 33 | C26: =IF(B26=0,"",B26/C$5) -> 0.94285714 | D26: 28500 | E26: =D26/B26 -> 863.63636 | F26: 28500 | G26: =IFERROR(F26/D26,"") -> 1 | H26: 29269 | I26: 28500 | J26: =IF(H26=0,"",H26-I26) -> 769 | K26: =IFERROR((H26-I26)/H26,"") -> 0.026273532 | L26: 32121 | M26: 23100 | N26: =IF(L26=0,"",L26-M26) -> 9021 | O26: =IFERROR((L26-M26)/L26,"") -> 0.28084431 | P26: =H26-L26 -> -2852 | Q26: =I26-M26 -> 5400 | R26: $4,000 appraisal fee
A27: =A25+7 -> 45753 | B27: 31 | C27: =IF(B27=0,"",B27/C$5) -> 0.88571429 | D27: 25850 | E27: =D27/B27 -> 833.87097 | F27: 23967 | G27: =IFERROR(F27/D27,"") -> 0.92715667
A28: =A27+7 -> 45760 | B28: 31 | C28: =IF(B28=0,"",B28/C$5) -> 0.88571429 | D28: 25850 | E28: =D28/B28 -> 833.87097 | F28: 25134 | G28: =IFERROR(F28/D28,"") -> 0.97230174
A29: =A28+7 -> 45767 | B29: 31 | C29: =IF(B29=0,"",B29/C$5) -> 0.88571429 | D29: 25850 | E29: =D29/B29 -> 833.87097 | F29: 26810 | G29: =IFERROR(F29/D29,"") -> 1.0371373
A30: =A29+7 -> 45774 | B30: 31 | C30: =IF(B30=0,"",B30/C$5) -> 0.88571429 | D30: 25850 | E30: =D30/B30 -> 833.87097 | F30: 27250 | G30: =IFERROR(F30/D30,"") -> 1.0541586
A31: Monthly Target | B31: 33 | C31: =IF(B31=0,"",B31/C$5) -> 0.94285714 | D31: 28500 | E31: =D31/B31 -> 863.63636 | F31: 28500 | G31: =IFERROR(F31/D31,"") -> 1 | H31: 28318 | I31: 28500 | J31: =IF(H31=0,"",H31-I31) -> -182 | K31: =IFERROR((H31-I31)/H31,"") -> -0.0064270076 | L31: 22554 | M31: 23100 | N31: =IF(L31=0,"",L31-M31) -> -546 | O31: =IFERROR((L31-M31)/L31,"") -> -0.024208566 | P31: =H31-L31 -> 5764 | Q31: =I31-M31 -> 5400
A32: =A30+7 -> 45781 | B32: 30 | C32: =IF(B32=0,"",B32/C$5) -> 0.85714286 | D32: 24875 | E32: =D32/B32 -> 829.16667 | F32: 14533 | G32: =IFERROR(F32/D32,"") -> 0.58424121
A33: =A32+7 -> 45788 | B33: 30 | C33: =IF(B33=0,"",B33/C$5) -> 0.85714286 | D33: 24875 | E33: =D33/B33 -> 829.16667 | F33: 20765 | G33: =IFERROR(F33/D33,"") -> 0.83477387
A34: =A33+7 -> 45795 | B34: 30 | C34: =IF(B34=0,"",B34/C$5) -> 0.85714286 | D34: 24875 | E34: =D34/B34 -> 829.16667 | F34: 20765 | G34: =IFERROR(F34/D34,"") -> 0.83477387
A35: =A34+7 -> 45802 | B35: 30 | C35: =IF(B35=0,"",B35/C$5) -> 0.85714286 | D35: 24875 | E35: =D35/B35 -> 829.16667 | F35: 22206 | G35: =IFERROR(F35/D35,"") -> 0.89270352
A36: Monthly Target | B36: 33 | C36: =IF(B36=0,"",B36/C$5) -> 0.94285714 | D36: 28500 | E36: =D36/B36 -> 863.63636 | F36: 28500 | G36: =IFERROR(F36/D36,"") -> 1 | H36: 25889 | I36: 28500 | J36: =IF(H36=0,"",H36-I36) -> -2611 | K36: =IFERROR((H36-I36)/H36,"") -> -0.10085364 | L36: 25143 | M36: 23100 | N36: =IF(L36=0,"",L36-M36) -> 2043 | O36: =IFERROR((L36-M36)/L36,"") -> 0.08125522 | P36: =H36-L36 -> 746 | Q36: =I36-M36 -> 5400 | R36: Additional $6700 in building improvments for sewer project
A37: =A35+7 -> 45809 | B37: 30 | C37: =IF(B37=0,"",B37/C$5) -> 0.85714286 | D37: 24875 | E37: =D37/B37 -> 829.16667 | F37: 8869 | G37: =IFERROR(F37/D37,"") -> 0.35654271
A38: =A37+7 -> 45816 | B38: 30 | C38: =IF(B38=0,"",B38/C$5) -> 0.85714286 | D38: 24875 | E38: =D38/B38 -> 829.16667 | F38: 19595 | G38: =IFERROR(F38/D38,"") -> 0.78773869
A39: =A38+7 -> 45823 | B39: 30 | C39: =IF(B39=0,"",B39/C$5) -> 0.85714286 | D39: 24875 | E39: =D39/B39 -> 829.16667 | F39: 21964 | G39: =IFERROR(F39/D39,"") -> 0.88297487
A40: =A39+7 -> 45830 | B40: 32 | C40: =IF(B40=0,"",B40/C$5) -> 0.91428571 | D40: 26725 | E40: =D40/B40 -> 835.15625 | F40: 21904 | G40: =IFERROR(F40/D40,"") -> 0.81960711
A41: =A40+7 -> 45837 | B41: 34 | C41: =IF(B41=0,"",B41/C$5) -> 0.97142857 | D41: 28517 | E41: =D41/B41 -> 838.73529 | F41: 22576 | G41: =IFERROR(F41/D41,"") -> 0.79166813
A42: Monthly Target | B42: 33 | C42: =IF(B42=0,"",B42/C$5) -> 0.94285714 | D42: 28500 | E42: =D42/B42 -> 863.63636 | F42: 28500 | G42: =IFERROR(F42/D42,"") -> 1 | H42: 20382 | I42: 28500 | J42: =IF(H42=0,"",H42-I42) -> -8118 | K42: =IFERROR((H42-I42)/H42,"") -> -0.39829261 | L42: 44238 | M42: 23100 | N42: =IF(L42=0,"",L42-M42) -> 21138 | O42: =IFERROR((L42-M42)/L42,"") -> 0.47782449 | P42: =H42-L42 -> -23856 | Q42: =I42-M42 -> 5400 | R42: 5980 In Building Improvmeents 129 Sewer Project ($20,000 in R&M in house for sewer project as well)
A43: =A41+7 -> 45844 | B43: 33 | C43: =IF(B43=0,"",B43/C$5) -> 0.94285714 | D43: 27967 | E43: =D43/B43 -> 847.48485 | F43: 25679 | G43: =IFERROR(F43/D43,"") -> 0.91818929
A44: =A43+7 -> 45851 | B44: 33 | C44: =IF(B44=0,"",B44/C$5) -> 0.94285714 | D44: 27967 | E44: =D44/B44 -> 847.48485 | F44: 26454 | G44: =IFERROR(F44/D44,"") -> 0.94590053
...

Sheet Bavarian Village
A1: KEY
A2: Manual Input
A3: Owner Input or Formula
A4: Formula | B4: 250 Angle Street
B5: # of Units | C5: 20 | I5: KPI Tracker
A10: Week Ending Sunday | B10: # of Occupied Units | C10: Occupancy % | D10: Total Leased Rent Amount $ | E10: Average Rent | F10: Total Collections to Date $ | G10: Collection Percentage | H10: Actual Revenue (Monthly Only) | I10: Budgeted Revenue (Monthly Only) | J10: Variance $ | K10: Variance % | L10: Actual Expense (Monthly Only) | M10: Budgeted Expense (Monthly Only | N10: Variance $ | O10: Variance % | P10: Net Income | Q10: Net Income Budgeted | R10: Notes:
A11: 45662 | B11: 18 | C11: =IF(B11=0,"",B11/C$5) -> 0.9 | D11: 17000 | E11: =IFERROR(D11/B11,"") -> 944.44444 | F11: 18045 | G11: =IFERROR(F11/D11,"") -> 1.0614706 | R11: 250 Angle Street, Bremen, Ohio
A12: =A11+7 -> 45669 | B12: 18 | C12: =IF(B12=0,"",B12/C$5) -> 0.9 | D12: 17000 | E12: =IFERROR(D12/B12,"") -> 944.44444 | F12: 19095 | G12: =IFERROR(F12/D12,"") -> 1.1232353
A13: =A12+7 -> 45676 | B13: 18 | C13: =IF(B13=0,"",B13/C$5) -> 0.9 | D13: 17000 | E13: =IFERROR(D13/B13,"") -> 944.44444 | F13: 19095 | G13: =IFERROR(F13/D13,"") -> 1.1232353
A14: =A13+7 -> 45683 | B14: 18 | C14: =IF(B14=0,"",B14/C$5) -> 0.9 | D14: 17000 | E14: =IFERROR(D14/B14,"") -> 944.44444 | F14: 19095 | G14: =IFERROR(F14/D14,"") -> 1.1232353
A15: Monthly Target | B15: 19 | C15: =IF(B15=0,"",B15/C$5) -> 0.95 | D15: 18000 | E15: =D15/B15 -> 947.36842 | F15: 18000 | G15: =IFERROR(F15/D15,"") -> 1 | H15: 21040 | I15: 18000 | J15: =IF(H15=0,"",H15-I15) -> 3040 | K15: =IFERROR((H15-I15)/H15,"") -> 0.14448669 | L15: 15803 | M15: 16100 | N15: =IF(L15=0,"",L15-M15) -> -297 | O15: =IFERROR((L15-M15)/L15,"") -> -0.0187939 | P15: =H15-L15 -> 5237 | Q15: =I15-M15 -> 1900
A16: =A14+7 -> 45690 | B16: 20 | C16: =IF(B16=0,"",B16/C$5) -> 1 | D16: 19025 | E16: =IFERROR(D16/B16,"") -> 951.25 | F16: 10870 | G16: =IFERROR(F16/D16,"") -> 0.57135348
A17: =A16+7 -> 45697 | B17: 20 | C17: =IF(B17=0,"",B17/C$5) -> 1 | D17: 19025 | E17: =IFERROR(D17/B17,"") -> 951.25 | F17: 17075 | G17: =IFERROR(F17/D17,"") -> 0.89750329
A18: =A17+7 -> 45704 | B18: 20 | C18: =IF(B18=0,"",B18/C$5) -> 1 | D18: 19025 | E18: =IFERROR(D18/B18,"") -> 951.25 | F18: 17075 | G18: =IFERROR(F18/D18,"") -> 0.89750329
A19: =A18+7 -> 45711 | B19: 20 | C19: =IF(B19=0,"",B19/C$5) -> 1 | D19: 19025 | E19: =IFERROR(D19/B19,"") -> 951.25 | F19: 17325 | G19: =IFERROR(F19/D19,"") -> 0.91064389
A20: Monthly Target | B20: 19 | C20: =IF(B20=0,"",B20/C$5) -> 0.95 | D20: 18000 | E20: =D20/B20 -> 947.36842 | F20: 18000 | G20: =IFERROR(F20/D20,"") -> 1 | H20: 22035 | I20: 18000 | J20: =IF(H20=0,"",H20-I20) -> 4035 | K20: =IFERROR((H20-I20)/H20,"") -> 0.18311777 | L20: 13082 | M20: 16100 | N20: =IF(L20=0,"",L20-M20) -> -3018 | O20: =IFERROR((L20-M20)/L20,"") -> -0.23069867 | P20: =H20-L20 -> 8953 | Q20: =I20-M20 -> 1900
A21: =A19+7 -> 45718 | B21: 20 | C21: =IF(B21=0,"",B21/C$5) -> 1 | D21: 19025 | E21: =IFERROR(D21/B21,"") -> 951.25 | F21: 13325 | G21: =IFERROR(F21/D21,"") -> 0.70039422
A22: =A21+7 -> 45725 | B22: 20 | C22: =IF(B22=0,"",B22/C$5) -> 1 | D22: 19025 | E22: =IFERROR(D22/B22,"") -> 951.25 | F22: 18075 | G22: =IFERROR(F22/D22,"") -> 0.9500657
A23: =A22+7 -> 45732 | B23: 20 | C23: =IF(B23=0,"",B23/C$5) -> 1 | D23: 19025 | E23: =IFERROR(D23/B23,"") -> 951.25 | F23: 18075 | G23: =IFERROR(F23/D23,"") -> 0.9500657
A24: =A23+7 -> 45739 | B24: 20 | C24: =IF(B24=0,"",B24/C$5) -> 1 | D24: 19025 | E24: =IFERROR(D24/B24,"") -> 951.25 | F24: 18075 | G24: =IFERROR(F24/D24,"") -> 0.9500657
A25: =A24+7 -> 45746 | B25: 20 | C25: =IF(B25=0,"",B25/C$5) -> 1 | D25: 19025 | E25: =IFERROR(D25/B25,"") -> 951.25 | F25: 18075 | G25: =IFERROR(F25/D25,"") -> 0.9500657
A26: Monthly Target | B26: 19 | C26: =IF(B26=0,"",B26/C$5) -> 0.95 | D26: 18000 | E26: =D26/B26 -> 947.36842 | F26: 18000 | G26: =IFERROR(F26/D26,"") -> 1 | H26: 18075 | I26: 18000 | J26: =IF(H26=0,"",H26-I26) -> 75 | K26: =IFERROR((H26-I26)/H26,"") -> 0.0041493776 | L26: 16516 | M26: 16100 | N26: =IF(L26=0,"",L26-M26) -> 416 | O26: =IFERROR((L26-M26)/L26,"") -> 0.025187697 | P26: =H26-L26 -> 1559 | Q26: =I26-M26 -> 1900
A27: =A25+7 -> 45753 | B27: 20 | C27: =IF(B27=0,"",B27/C$5) -> 1 | D27: 19025 | E27: =IFERROR(D27/B27,"") -> 951.25 | F27: 17125 | G27: =IFERROR(F27/D27,"") -> 0.90013141
A28: =A27+7 -> 45760 | B28: 20 | C28: =IF(B28=0,"",B28/C$5) -> 1 | D28: 19025 | E28: =IFERROR(D28/B28,"") -> 951.25 | F28: 17125 | G28: =IFERROR(F28/D28,"") -> 0.90013141
A29: =A28+7 -> 45767 | B29: 19 | C29: =IF(B29=0,"",B29/C$5) -> 0.95 | D29: 18250 | E29: =IFERROR(D29/B29,"") -> 960.52632 | F29: 17125 | G29: =IFERROR(F29/D29,"") -> 0.93835616
A30: =A29+7 -> 45774 | B30: 19 | C30: =IF(B30=0,"",B30/C$5) -> 0.95 | D30: 18250 | E30: =IFERROR(D30/B30,"") -> 960.52632 | F30: 17125 | G30: =IFERROR(F30/D30,"") -> 0.93835616
A31: Monthly Target | B31: 19 | C31: =IF(B31=0,"",B31/C$5) -> 0.95 | D31: 18000 | E31: =D31/B31 -> 947.36842 | F31: 18000 | G31: =IFERROR(F31/D31,"") -> 1 | H31: 17125 | I31: 18000 | J31: =IF(H31=0,"",H31-I31) -> -875 | K31: =IFERROR((H31-I31)/H31,"") -> -0.051094891 | L31: 23963 | M31: 16100 | N31: =IF(L31=0,"",L31-M31) -> 7863 | O31: =IFERROR((L31-M31)/L31,"") -> 0.32813087 | P31: =H31-L31 -> -6838 | Q31: =I31-M31 -> 1900 | R31: OUCU double mortgage payment
A32: =A30+7 -> 45781 | B32: 20 | C32: =IF(B32=0,"",B32/C$5) -> 1 | D32: 19075 | E32: =IFERROR(D32/B32,"") -> 953.75 | F32: 15975 | G32: =IFERROR(F32/D32,"") -> 0.83748362
A33: =A32+7 -> 45788 | B33: 20 | C33: =IF(B33=0,"",B33/C$5) -> 1 | D33: 19075 | E33: =IFERROR(D33/B33,"") -> 953.75 | F33: 21680 | G33: =IFERROR(F33/D33,"") -> 1.1365662
A34: =A33+7 -> 45795 | B34: 20 | C34: =IF(B34=0,"",B34/C$5) -> 1 | D34: 19075 | E34: =IFERROR(D34/B34,"") -> 953.75 | F34: 21930 | G34: =IFERROR(F34/D34,"") -> 1.1496723
A35: =A34+7 -> 45802 | B35: 20 | C35: =IF(B35=0,"",B35/C$5) -> 1 | D35: 19075 | E35: =IFERROR(D35/B35,"") -> 953.75 | F35: 21930 | G35: =IFERROR(F35/D35,"") -> 1.1496723
A36: Monthly Target | B36: 19 | C36: =IF(B36=0,"",B36/C$5) -> 0.95 | D36: 18000 | E36: =D36/B36 -> 947.36842 | F36: 18000 | G36: =IFERROR(F36/D36,"") -> 1 | H36: 30293 | I36: 18000 | J36: =IF(H36=0,"",H36-I36) -> 12293 | K36: =IFERROR((H36-I36)/H36,"") -> 0.40580332 | L36: 6125 | M36: 16100 | N36: =IF(L36=0,"",L36-M36) -> -9975 | O36: =IFERROR((L36-M36)/L36,"") -> -1.6285714 | P36: =H36-L36 -> 24168 | Q36: =I36-M36 -> 1900 | R36: Mortgage credited in June and double payment the month before
A37: =A35+7 -> 45809 | B37: 19 | C37: =IF(B37=0,"",B37/C$5) -> 0.95 | D37: 18125 | E37: =IFERROR(D37/B37,"") -> 953.94737 | F37: 13225 | G37: =IFERROR(F37/D37,"") -> 0.72965517
A38: =A37+7 -> 45816 | B38: 19 | C38: =IF(B38=0,"",B38/C$5) -> 0.95 | D38: 18125 | E38: =IFERROR(D38/B38,"") -> 953.94737 | F38: 18025 | G38: =IFERROR(F38/D38,"") -> 0.99448276
A39: =A38+7 -> 45823 | B39: 19 | C39: =IF(B39=0,"",B39/C$5) -> 0.95 | D39: 18125 | E39: =IFERROR(D39/B39,"") -> 953.94737 | F39: 18025 | G39: =IFERROR(F39/D39,"") -> 0.99448276
A40: =A39+7 -> 45830 | B40: 19 | C40: =IF(B40=0,"",B40/C$5) -> 0.95 | D40: 18125 | E40: =IFERROR(D40/B40,"") -> 953.94737 | F40: 18025 | G40: =IFERROR(F40/D40,"") -> 0.99448276
A41: =A40+7 -> 45837 | B41: 19 | C41: =IF(B41=0,"",B41/C$5) -> 0.95 | D41: 18125 | E41: =IFERROR(D41/B41,"") -> 953.94737 | F41: 18025 | G41: =IFERROR(F41/D41,"") -> 0.99448276
A42: Monthly Target | B42: 19 | C42: =IF(B42=0,"",B42/C$5) -> 0.95 | D42: 18000 | E42: =D42/B42 -> 947.36842 | F42: 18000 | G42: =IFERROR(F42/D42,"") -> 1 | H42: 11643 | I42: 18000 | J42: =IF(H42=0,"",H42-I42) -> -6357 | K42: =IFERROR((H42-I42)/H42,"") -> -0.5459933 | L42: 26152 | M42: 16100 | N42: =IF(L42=0,"",L42-M42) -> 10052 | O42: =IFERROR((L42-M42)/L42,"") -> 0.38436831 | P42: =H42-L42 -> -14509 | Q42: =I42-M42 -> 1900 | R42: Double Mortgage Payment & prepaid rent reduced income
A43: =A41+7 -> 45844 | B43: 19 | C43: =IF(B43=0,"",B43/C$5) -> 0.95 | D43: 18175 | E43: =IFERROR(D43/B43,"") -> 956.57895 | F43: 16750 | G43: =IFERROR(F43/D43,"") -> 0.9215956
A44: =A43+7 -> 45851 | B44: 20 | C44: =IF(B44=0,"",B44/C$5) -> 1 | D44: 19175 | E44: =IFERROR(D44/B44,"") -> 958.75 | F44: 17750 | G44: =IFERROR(F44/D44,"") -> 0.92568449
...

Sheet Glasstown Holdings
A1: KEY
A2: Manual Input
A3: Owner Input or Formula
A4: Formula | B4: Slocum & 6th
B5: # of Units | C5: 16 | I5: KPI Tracker
A10: Week Ending Sunday | B10: # of Occupied Units | C10: Occupancy % | D10: Total Leased Rent Amount $ | E10: Average Rent | F10: Total Collections to Date $ | G10: Collection Percentage | H10: Actual Revenue (Monthly Only) | I10: Budgeted Revenue (Monthly Only) | J10: Variance $ | K10: Variance % | L10: Actual Expense (Monthly Only) | M10: Budgeted Expense (Monthly Only | N10: Variance $ | O10: Variance % | P10: Net Income | Q10: Net Income Budgeted | R10: Notes:
A11: 45662 | B11: 16 | C11: =IF(B11=0,"",B11/C$5) -> 1 | D11: 12875 | E11: =IFERROR(D11/B11,"") -> 804.6875 | F11: 11580 | G11: =IFERROR(F11/D11,"") -> 0.89941748 | R11: 709 W 6th and 234 Slocum Ave Lancaster, Ohio 43130 (6 & 10 unit)
A12: =A11+7 -> 45669 | B12: 16 | C12: =IF(B12=0,"",B12/C$5) -> 1 | D12: 12875 | E12: =IFERROR(D12/B12,"") -> 804.6875 | F12: 12025 | G12: =IFERROR(F12/D12,"") -> 0.93398058
A13: =A12+7 -> 45676 | B13: 16 | C13: =IF(B13=0,"",B13/C$5) -> 1 | D13: 12875 | E13: =IFERROR(D13/B13,"") -> 804.6875 | F13: 12025 | G13: =IFERROR(F13/D13,"") -> 0.93398058
A14: =A13+7 -> 45683 | B14: 16 | C14: =IF(B14=0,"",B14/C$5) -> 1 | D14: 12875 | E14: =IFERROR(D14/B14,"") -> 804.6875 | F14: 12025 | G14: =IFERROR(F14/D14,"") -> 0.93398058
A15: Monthly Target | B15: 15 | C15: =IF(B15=0,"",B15/C$5) -> 0.9375 | D15: 12250 | E15: =D15/B15 -> 816.66667 | F15: 12250 | G15: =IFERROR(F15/D15,"") -> 1 | H15: 12025 | I15: 12250 | J15: =IF(H15=0,"",H15-I15) -> -225 | K15: =IFERROR((H15-I15)/H15,"") -> -0.018711019 | L15: 12655 | M15: 9300 | N15: =IF(L15=0,"",L15-M15) -> 3355 | O15: =IFERROR((L15-M15)/L15,"") -> 0.2651126 | P15: =H15-L15 -> -630 | Q15: =I15-M15 -> 2950 | R15: Paid Property Insurance for the year
A16: =A14+7 -> 45690 | B16: 16 | C16: =IF(B16=0,"",B16/C$5) -> 1 | D16: 12875 | E16: =IFERROR(D16/B16,"") -> 804.6875 | F16: 4198 | G16: =IFERROR(F16/D16,"") -> 0.32605825
A17: =A16+7 -> 45697 | B17: 16 | C17: =IF(B17=0,"",B17/C$5) -> 1 | D17: 12875 | E17: =IFERROR(D17/B17,"") -> 804.6875 | F17: 11175 | G17: =IFERROR(F17/D17,"") -> 0.86796116
A18: =A17+7 -> 45704 | B18: 16 | C18: =IF(B18=0,"",B18/C$5) -> 1 | D18: 12875 | E18: =IFERROR(D18/B18,"") -> 804.6875 | F18: 12025 | G18: =IFERROR(F18/D18,"") -> 0.93398058
A19: =A18+7 -> 45711 | B19: 16 | C19: =IF(B19=0,"",B19/C$5) -> 1 | D19: 12875 | E19: =IFERROR(D19/B19,"") -> 804.6875 | F19: 12025 | G19: =IFERROR(F19/D19,"") -> 0.93398058
A20: Monthly Target | B20: 15 | C20: =IF(B20=0,"",B20/C$5) -> 0.9375 | D20: 12250 | E20: =D20/B20 -> 816.66667 | F20: 12250 | G20: =IFERROR(F20/D20,"") -> 1 | H20: 13814 | I20: 12250 | J20: =IF(H20=0,"",H20-I20) -> 1564 | K20: =IFERROR((H20-I20)/H20,"") -> 0.11321847 | L20: 12663 | M20: 9300 | N20: =IF(L20=0,"",L20-M20) -> 3363 | O20: =IFERROR((L20-M20)/L20,"") -> 0.26557688 | P20: =H20-L20 -> 1151 | Q20: =I20-M20 -> 2950 | R20: $769 in building improvements not in expenses. & property taxes 1/2 year paid
A21: =A19+7 -> 45718 | B21: 16 | C21: =IF(B21=0,"",B21/C$5) -> 1 | D21: 12875 | E21: =IFERROR(D21/B21,"") -> 804.6875 | F21: 4344 | G21: =IFERROR(F21/D21,"") -> 0.33739806
A22: =A21+7 -> 45725 | B22: 16 | C22: =IF(B22=0,"",B22/C$5) -> 1 | D22: 12875 | E22: =IFERROR(D22/B22,"") -> 804.6875 | F22: 11600 | G22: =IFERROR(F22/D22,"") -> 0.90097087
A23: =A22+7 -> 45732 | B23: 15 | C23: =IF(B23=0,"",B23/C$5) -> 0.9375 | D23: 12025 | E23: =IFERROR(D23/B23,"") -> 801.66667 | F23: 12025 | G23: =IFERROR(F23/D23,"") -> 1
A24: =A23+7 -> 45739 | B24: 15 | C24: =IF(B24=0,"",B24/C$5) -> 0.9375 | D24: 12025 | E24: =IFERROR(D24/B24,"") -> 801.66667 | F24: 12840 | G24: =IFERROR(F24/D24,"") -> 1.0677755
A25: =A24+7 -> 45746 | B25: 15 | C25: =IF(B25=0,"",B25/C$5) -> 0.9375 | D25: 12025 | E25: =IFERROR(D25/B25,"") -> 801.66667 | F25: 12840 | G25: =IFERROR(F25/D25,"") -> 1.0677755
A26: Monthly Target | B26: 15 | C26: =IF(B26=0,"",B26/C$5) -> 0.9375 | D26: 12250 | E26: =D26/B26 -> 816.66667 | F26: 12250 | G26: =IFERROR(F26/D26,"") -> 1 | H26: 12840 | I26: 12250 | J26: =IF(H26=0,"",H26-I26) -> 590 | K26: =IFERROR((H26-I26)/H26,"") -> 0.045950156 | L26: 14039 | M26: 9300 | N26: =IF(L26=0,"",L26-M26) -> 4739 | O26: =IFERROR((L26-M26)/L26,"") -> 0.33755966 | P26: =H26-L26 -> -1199 | Q26: =I26-M26 -> 2950 | R26: $6,200 property insurance for the year
A27: =A25+7 -> 45753 | B27: 15 | C27: =IF(B27=0,"",B27/C$5) -> 0.9375 | D27: 12025 | E27: =IFERROR(D27/B27,"") -> 801.66667 | F27: 11600 | G27: =IFERROR(F27/D27,"") -> 0.96465696
A28: =A27+7 -> 45760 | B28: 16 | C28: =IF(B28=0,"",B28/C$5) -> 1 | D28: 12875 | E28: =IFERROR(D28/B28,"") -> 804.6875 | F28: 12025 | G28: =IFERROR(F28/D28,"") -> 0.93398058
A29: =A28+7 -> 45767 | B29: 16 | C29: =IF(B29=0,"",B29/C$5) -> 1 | D29: 12875 | E29: =IFERROR(D29/B29,"") -> 804.6875 | F29: 12662 | G29: =IFERROR(F29/D29,"") -> 0.98345631
A30: =A29+7 -> 45774 | B30: 16 | C30: =IF(B30=0,"",B30/C$5) -> 1 | D30: 12875 | E30: =IFERROR(D30/B30,"") -> 804.6875 | F30: 12662 | G30: =IFERROR(F30/D30,"") -> 0.98345631
A31: Monthly Target | B31: 15 | C31: =IF(B31=0,"",B31/C$5) -> 0.9375 | D31: 12250 | E31: =D31/B31 -> 816.66667 | F31: 12250 | G31: =IFERROR(F31/D31,"") -> 1 | H31: 14005 | I31: 12250 | J31: =IF(H31=0,"",H31-I31) -> 1755 | K31: =IFERROR((H31-I31)/H31,"") -> 0.12531239 | L31: 9954 | M31: 9300 | N31: =IF(L31=0,"",L31-M31) -> 654 | O31: =IFERROR((L31-M31)/L31,"") -> 0.06570223 | P31: =H31-L31 -> 4051 | Q31: =I31-M31 -> 2950
A32: =A30+7 -> 45781 | B32: 16 | C32: =IF(B32=0,"",B32/C$5) -> 1 | D32: 12875 | E32: =IFERROR(D32/B32,"") -> 804.6875 | F32: 12005 | G32: =IFERROR(F32/D32,"") -> 0.93242718
A33: =A32+7 -> 45788 | B33: 16 | C33: =IF(B33=0,"",B33/C$5) -> 1 | D33: 12875 | E33: =IFERROR(D33/B33,"") -> 804.6875 | F33: 12855 | G33: =IFERROR(F33/D33,"") -> 0.9984466
A34: =A33+7 -> 45795 | B34: 16 | C34: =IF(B34=0,"",B34/C$5) -> 1 | D34: 12875 | E34: =IFERROR(D34/B34,"") -> 804.6875 | F34: 12855 | G34: =IFERROR(F34/D34,"") -> 0.9984466
A35: =A34+7 -> 45802 | B35: 16 | C35: =IF(B35=0,"",B35/C$5) -> 1 | D35: 12845 | E35: =IFERROR(D35/B35,"") -> 802.8125 | F35: 12855 | G35: =IFERROR(F35/D35,"") -> 1.0007785
A36: Monthly Target | B36: 15 | C36: =IF(B36=0,"",B36/C$5) -> 0.9375 | D36: 12250 | E36: =D36/B36 -> 816.66667 | F36: 12250 | G36: =IFERROR(F36/D36,"") -> 1 | H36: 13249 | I36: 12250 | J36: =IF(H36=0,"",H36-I36) -> 999 | K36: =IFERROR((H36-I36)/H36,"") -> 0.075401917 | L36: 10849 | M36: 9300 | N36: =IF(L36=0,"",L36-M36) -> 1549 | O36: =IFERROR((L36-M36)/L36,"") -> 0.14277814 | P36: =H36-L36 -> 2400 | Q36: =I36-M36 -> 2950 | R36: Flood insuranc eon Slocum for the year
A37: =A35+7 -> 45809 | B37: 16 | C37: =IF(B37=0,"",B37/C$5) -> 1 | D37: 12900 | E37: =IFERROR(D37/B37,"") -> 806.25 | F37: 4001 | G37: =IFERROR(F37/D37,"") -> 0.31015504
A38: =A37+7 -> 45816 | B38: 16 | C38: =IF(B38=0,"",B38/C$5) -> 1 | D38: 12900 | E38: =IFERROR(D38/B38,"") -> 806.25 | F38: 11343 | G38: =IFERROR(F38/D38,"") -> 0.87930233
A39: =A38+7 -> 45823 | B39: 16 | C39: =IF(B39=0,"",B39/C$5) -> 1 | D39: 12900 | E39: =IFERROR(D39/B39,"") -> 806.25 | F39: 12920 | G39: =IFERROR(F39/D39,"") -> 1.0015504
A40: =A39+7 -> 45830 | B40: 16 | C40: =IF(B40=0,"",B40/C$5) -> 1 | D40: 12900 | E40: =IFERROR(D40/B40,"") -> 806.25 | F40: 12920 | G40: =IFERROR(F40/D40,"") -> 1.0015504
A41: =A40+7 -> 45837 | B41: 15 | C41: =IF(B41=0,"",B41/C$5) -> 0.9375 | D41: 12050 | E41: =IFERROR(D41/B41,"") -> 803.33333 | F41: 12920 | G41: =IFERROR(F41/D41,"") -> 1.0721992
A42: Monthly Target | B42: 15 | C42: =IF(B42=0,"",B42/C$5) -> 0.9375 | D42: 12250 | E42: =D42/B42 -> 816.66667 | F42: 12250 | G42: =IFERROR(F42/D42,"") -> 1 | H42: 13609 | I42: 12250 | J42: =IF(H42=0,"",H42-I42) -> 1359 | K42: =IFERROR((H42-I42)/H42,"") -> 0.099860387 | L42: 9391 | M42: 9300 | N42: =IF(L42=0,"",L42-M42) -> 91 | O42: =IFERROR((L42-M42)/L42,"") -> 0.0096901288 | P42: =H42-L42 -> 4218 | Q42: =I42-M42 -> 2950 | R42: Stellar
A43: =A41+7 -> 45844 | B43: 15 | C43: =IF(B43=0,"",B43/C$5) -> 0.9375 | D43: 12110 | E43: =IFERROR(D43/B43,"") -> 807.33333 | F43: 10723 | G43: =IFERROR(F43/D43,"") -> 0.88546656
A44: =A43+7 -> 45851 | B44: 16 | C44: =IF(B44=0,"",B44/C$5) -> 1 | D44: 12960 | E44: =IFERROR(D44/B44,"") -> 810 | F44: 10723 | G44: =IFERROR(F44/D44,"") -> 0.82739198
...

Sheet Rain Tree Apts
A1: KEY
A2: Manual Input
A3: Owner Input or Formula
A4: Formula | B4: Rain Tree Apartments
B5: # of Units | C5: 8 | I5: KPI Tracker
A10: Week Ending Sunday | B10: # of Occupied Units | C10: Occupancy % | D10: Total Leased Rent Amount $ | E10: Average Rent | F10: Total Collections to Date $ | G10: Collection Percentage | H10: Actual Revenue (Monthly Only) | I10: Budgeted Revenue (Monthly Only) | J10: Variance $ | K10: Variance % | L10: Actual Expense (Monthly Only) | M10: Budgeted Expense (Monthly Only | N10: Variance $ | O10: Variance % | P10: Net Income | Q10: Net Income Budgeted | R10: Total Expenses
A11: 45662 | B11: 6 | C11: =IF(B11=0,"",B11/C$5) -> 0.75 | D11: 6400 | E11: =IFERROR(D11/B11,"") -> 1066.6667 | F11: 6551 | G11: =IFERROR(F11/D11,"") -> 1.0235938 | R11: 1442 Tiki Lane, Lancaster, Ohio 43130
A12: =A11+7 -> 45669 | B12: 6 | C12: =IF(B12=0,"",B12/C$5) -> 0.75 | D12: 6400 | E12: =IFERROR(D12/B12,"") -> 1066.6667 | F12: 7041 | G12: =IFERROR(F12/D12,"") -> 1.1001562
A13: =A12+7 -> 45676 | B13: 6 | C13: =IF(B13=0,"",B13/C$5) -> 0.75 | D13: 6500 | E13: =IFERROR(D13/B13,"") -> 1083.3333 | F13: 8101 | G13: =IFERROR(F13/D13,"") -> 1.2463077
A14: =A13+7 -> 45683 | B14: 6 | C14: =IF(B14=0,"",B14/C$5) -> 0.75 | D14: 6500 | E14: =IFERROR(D14/B14,"") -> 1083.3333 | F14: 8101 | G14: =IFERROR(F14/D14,"") -> 1.2463077
A15: Monthly Target | B15: 7 | C15: =IF(B15=0,"",B15/C$5) -> 0.875 | D15: 7500 | E15: =D15/B15 -> 1071.4286 | F15: 7500 | G15: =IFERROR(F15/D15,"") -> 1 | H15: 8101 | I15: 7500 | J15: =IF(H15=0,"",H15-I15) -> 601 | K15: =IFERROR((H15-I15)/H15,"") -> 0.074188372 | L15: 8925 | M15: 6175 | N15: =IF(L15=0,"",L15-M15) -> 2750 | O15: =IFERROR((L15-M15)/L15,"") -> 0.30812325 | P15: =H15-L15 -> -824 | Q15: =I15-M15 -> 1325 | R15: Really high water bill (addressed)
A16: =A14+7 -> 45690 | B16: 6 | C16: =IF(B16=0,"",B16/C$5) -> 0.75 | D16: 6500 | E16: =IFERROR(D16/B16,"") -> 1083.3333 | F16: 533 | G16: =IFERROR(F16/D16,"") -> 0.082
A17: =A16+7 -> 45697 | B17: 6 | C17: =IF(B17=0,"",B17/C$5) -> 0.75 | D17: 6500 | E17: =IFERROR(D17/B17,"") -> 1083.3333 | F17: 6537 | G17: =IFERROR(F17/D17,"") -> 1.0056923
A18: =A17+7 -> 45704 | B18: 6 | C18: =IF(B18=0,"",B18/C$5) -> 0.75 | D18: 6500 | E18: =IFERROR(D18/B18,"") -> 1083.3333 | F18: 6537 | G18: =IFERROR(F18/D18,"") -> 1.0056923
A19: =A18+7 -> 45711 | B19: 6 | C19: =IF(B19=0,"",B19/C$5) -> 0.75 | D19: 6500 | E19: =IFERROR(D19/B19,"") -> 1083.3333 | F19: 6897 | G19: =IFERROR(F19/D19,"") -> 1.0610769
A20: Monthly Target | B20: 7 | C20: =IF(B20=0,"",B20/C$5) -> 0.875 | D20: 7500 | E20: =D20/B20 -> 1071.4286 | F20: 7500 | G20: =IFERROR(F20/D20,"") -> 1 | H20: 7444 | I20: 7500 | J20: =IF(H20=0,"",H20-I20) -> -56 | K20: =IFERROR((H20-I20)/H20,"") -> -0.0075228372 | L20: 8526 | M20: 6175 | N20: =IF(L20=0,"",L20-M20) -> 2351 | O20: =IFERROR((L20-M20)/L20,"") -> 0.27574478 | P20: =H20-L20 -> -1082 | Q20: =I20-M20 -> 1325 | R20: $730 building improvements not in expenses. (1/2 year property taxes paid)
A21: =A19+7 -> 45718 | B21: 8 | C21: =IF(B21=0,"",B21/C$5) -> 1 | D21: 8850 | E21: =IFERROR(D21/B21,"") -> 1106.25 | F21: 533 | G21: =IFERROR(F21/D21,"") -> 0.060225989
A22: =A21+7 -> 45725 | B22: 8 | C22: =IF(B22=0,"",B22/C$5) -> 1 | D22: 8850 | E22: =IFERROR(D22/B22,"") -> 1106.25 | F22: 7765 | G22: =IFERROR(F22/D22,"") -> 0.87740113
A23: =A22+7 -> 45732 | B23: 8 | C23: =IF(B23=0,"",B23/C$5) -> 1 | D23: 8850 | E23: =IFERROR(D23/B23,"") -> 1106.25 | F23: 7765 | G23: =IFERROR(F23/D23,"") -> 0.87740113
A24: =A23+7 -> 45739 | B24: 8 | C24: =IF(B24=0,"",B24/C$5) -> 1 | D24: 8850 | E24: =IFERROR(D24/B24,"") -> 1106.25 | F24: 7765 | G24: =IFERROR(F24/D24,"") -> 0.87740113
A25: =A24+7 -> 45746 | B25: 8 | C25: =IF(B25=0,"",B25/C$5) -> 1 | D25: 8850 | E25: =IFERROR(D25/B25,"") -> 1106.25 | F25: 7765 | G25: =IFERROR(F25/D25,"") -> 0.87740113
A26: Monthly Target | B26: 7 | C26: =IF(B26=0,"",B26/C$5) -> 0.875 | D26: 7500 | E26: =D26/B26 -> 1071.4286 | F26: 7500 | G26: =IFERROR(F26/D26,"") -> 1 | H26: 7765 | I26: 7500 | J26: =IF(H26=0,"",H26-I26) -> 265 | K26: =IFERROR((H26-I26)/H26,"") -> 0.034127495 | L26: 9661 | M26: 6175 | N26: =IF(L26=0,"",L26-M26) -> 3486 | O26: =IFERROR((L26-M26)/L26,"") -> 0.36083221 | P26: =H26-L26 -> -1896 | Q26: =I26-M26 -> 1325 | R26: $2,500 building improvements
A27: =A25+7 -> 45753 | B27: 8 | C27: =IF(B27=0,"",B27/C$5) -> 1 | D27: 8850 | E27: =IFERROR(D27/B27,"") -> 1106.25 | F27: 6902 | G27: =IFERROR(F27/D27,"") -> 0.77988701
A28: =A27+7 -> 45760 | B28: 8 | C28: =IF(B28=0,"",B28/C$5) -> 1 | D28: 8850 | E28: =IFERROR(D28/B28,"") -> 1106.25 | F28: 8490 | G28: =IFERROR(F28/D28,"") -> 0.95932203
A29: =A28+7 -> 45767 | B29: 8 | C29: =IF(B29=0,"",B29/C$5) -> 1 | D29: 8850 | E29: =IFERROR(D29/B29,"") -> 1106.25 | F29: 8850 | G29: =IFERROR(F29/D29,"") -> 1
A30: =A29+7 -> 45774 | B30: 8 | C30: =IF(B30=0,"",B30/C$5) -> 1 | D30: 8850 | E30: =IFERROR(D30/B30,"") -> 1106.25 | F30: 8850 | G30: =IFERROR(F30/D30,"") -> 1
A31: Monthly Target | B31: 7 | C31: =IF(B31=0,"",B31/C$5) -> 0.875 | D31: 7500 | E31: =D31/B31 -> 1071.4286 | F31: 7500 | G31: =IFERROR(F31/D31,"") -> 1 | H31: 9137 | I31: 7500 | J31: =IF(H31=0,"",H31-I31) -> 1637 | K31: =IFERROR((H31-I31)/H31,"") -> 0.17916165 | L31: 4236 | M31: 6175 | N31: =IF(L31=0,"",L31-M31) -> -1939 | O31: =IFERROR((L31-M31)/L31,"") -> -0.45774315 | P31: =H31-L31 -> 4901 | Q31: =I31-M31 -> 1325 | R31: No OUCU mortgage in April
A32: =A30+7 -> 45781 | B32: 8 | C32: =IF(B32=0,"",B32/C$5) -> 1 | D32: 8950 | E32: =IFERROR(D32/B32,"") -> 1118.75 | F32: 6757 | G32: =IFERROR(F32/D32,"") -> 0.75497207
A33: =A32+7 -> 45788 | B33: 8 | C33: =IF(B33=0,"",B33/C$5) -> 1 | D33: 8950 | E33: =IFERROR(D33/B33,"") -> 1118.75 | F33: 9834 | G33: =IFERROR(F33/D33,"") -> 1.098771
A34: =A33+7 -> 45795 | B34: 8 | C34: =IF(B34=0,"",B34/C$5) -> 1 | D34: 8950 | E34: =IFERROR(D34/B34,"") -> 1118.75 | F34: 9834 | G34: =IFERROR(F34/D34,"") -> 1.098771
A35: =A34+7 -> 45802 | B35: 8 | C35: =IF(B35=0,"",B35/C$5) -> 1 | D35: 8950 | E35: =IFERROR(D35/B35,"") -> 1118.75 | F35: 9834 | G35: =IFERROR(F35/D35,"") -> 1.098771
A36: Monthly Target | B36: 7 | C36: =IF(B36=0,"",B36/C$5) -> 0.875 | D36: 7500 | E36: =D36/B36 -> 1071.4286 | F36: 7500 | G36: =IFERROR(F36/D36,"") -> 1 | H36: 9909 | I36: 7500 | J36: =IF(H36=0,"",H36-I36) -> 2409 | K36: =IFERROR((H36-I36)/H36,"") -> 0.24311232 | L36: 7489 | M36: 6175 | N36: =IF(L36=0,"",L36-M36) -> 1314 | O36: =IFERROR((L36-M36)/L36,"") -> 0.17545734 | P36: =H36-L36 -> 2420 | Q36: =I36-M36 -> 1325
A37: =A35+7 -> 45809 | B37: 8 | C37: =IF(B37=0,"",B37/C$5) -> 1 | D37: 8950 | E37: =IFERROR(D37/B37,"") -> 1118.75 | F37: 1418 | G37: =IFERROR(F37/D37,"") -> 0.15843575
A38: =A37+7 -> 45816 | B38: 8 | C38: =IF(B38=0,"",B38/C$5) -> 1 | D38: 8950 | E38: =IFERROR(D38/B38,"") -> 1118.75 | F38: 8950 | G38: =IFERROR(F38/D38,"") -> 1
A39: =A38+7 -> 45823 | B39: 8 | C39: =IF(B39=0,"",B39/C$5) -> 1 | D39: 8950 | E39: =IFERROR(D39/B39,"") -> 1118.75 | F39: 8950 | G39: =IFERROR(F39/D39,"") -> 1
A40: =A39+7 -> 45830 | B40: 8 | C40: =IF(B40=0,"",B40/C$5) -> 1 | D40: 8950 | E40: =IFERROR(D40/B40,"") -> 1118.75 | F40: 8950 | G40: =IFERROR(F40/D40,"") -> 1
A41: =A40+7 -> 45837 | B41: 8 | C41: =IF(B41=0,"",B41/C$5) -> 1 | D41: 8950 | E41: =IFERROR(D41/B41,"") -> 1118.75 | F41: 8950 | G41: =IFERROR(F41/D41,"") -> 1
A42: Monthly Target | B42: 7 | C42: =IF(B42=0,"",B42/C$5) -> 0.875 | D42: 7500 | E42: =D42/B42 -> 1071.4286 | F42: 7500 | G42: =IFERROR(F42/D42,"") -> 1 | H42: 8685 | I42: 7500 | J42: =IF(H42=0,"",H42-I42) -> 1185 | K42: =IFERROR((H42-I42)/H42,"") -> 0.13644214 | L42: 9138 | M42: 6175 | N42: =IF(L42=0,"",L42-M42) -> 2963 | O42: =IFERROR((L42-M42)/L42,"") -> 0.32425038 | P42: =H42-L42 -> -453 | Q42: =I42-M42 -> 1325 | R42: Property Insurance For Year
A43: =A41+7 -> 45844 | B43: 8 | C43: =IF(B43=0,"",B43/C$5) -> 1 | D43: 8950 | E43: =IFERROR(D43/B43,"") -> 1118.75 | F43: 8423 | G43: =IFERROR(F43/D43,"") -> 0.94111732
A44: =A43+7 -> 45851 | B44: 8 | C44: =IF(B44=0,"",B44/C$5) -> 1 | D44: 8950 | E44: =IFERROR(D44/B44,"") -> 1118.75 | F44: 8423 | G44: =IFERROR(F44/D44,"") -> 0.94111732
...

Sheet RDE Central
A1: KEY
A2: Manual Input
A3: Owner Input or Formula
A4: Formula | B4: RDE Central
B5: # of Units | C5: 14 | E5: 45870 | I5: KPI Tracker
B6: 3/16/2025 up to 17 Units | D6: 16 | E6: 18
A10: Week Ending Sunday | B10: # of Occupied Units | C10: Occupancy % | D10: Total Leased Rent Amount $ | E10: Average Rent | F10: Total Collections to Date $ | G10: Collection Percentage | H10: Actual Revenue (Monthly Only) | I10: Budgeted Revenue (Monthly Only) | J10: Variance $ | K10: Variance % | L10: Actual Expense (Monthly Only) | M10: Budgeted Expense (Monthly Only | N10: Variance $ | O10: Variance % | P10: Net Income | Q10: Net Income Budgeted | R10: Total Expenses
A11: 45662 | B11: 12 | C11: =IF(B11=0,"",B11/C$5) -> 0.85714286 | D11: 10275 | E11: =IFERROR(D11/B11,"") -> 856.25 | F11: 8775 | G11: =IFERROR(F11/D11,"") -> 0.8540146 | R11: 1153-1155 N Columbus, 1233 Williams, 508 N Columbus, 530-532 N Columbus, 544-566 E Wheeling
A12: =A11+7 -> 45669 | B12: 12 | C12: =IF(B12=0,"",B12/C$5) -> 0.85714286 | D12: 10275 | E12: =IFERROR(D12/B12,"") -> 856.25 | F12: 9575 | G12: =IFERROR(F12/D12,"") -> 0.93187348
A13: =A12+7 -> 45676 | B13: 12 | C13: =IF(B13=0,"",B13/C$5) -> 0.85714286 | D13: 10275 | E13: =IFERROR(D13/B13,"") -> 856.25 | F13: 9575 | G13: =IFERROR(F13/D13,"") -> 0.93187348
A14: =A13+7 -> 45683 | B14: 12 | C14: =IF(B14=0,"",B14/C$5) -> 0.85714286 | D14: 10275 | E14: =IFERROR(D14/B14,"") -> 856.25 | F14: 9575 | G14: =IFERROR(F14/D14,"") -> 0.93187348
A15: Monthly Target | B15: 12 | C15: =IF(B15=0,"",B15/C$5) -> 0.85714286 | D15: 10850 | E15: =D15/B15 -> 904.16667 | F15: 10850 | G15: =IFERROR(F15/D15,"") -> 1 | H15: 9575 | I15: 10850 | J15: =IF(H15=0,"",H15-I15) -> -1275 | K15: =IFERROR((H15-I15)/H15,"") -> -0.13315927 | L15: 7650 | M15: 10000 | N15: =IF(L15=0,"",L15-M15) -> -2350 | O15: =IFERROR((L15-M15)/L15,"") -> -0.30718954 | P15: =H15-L15 -> 1925 | Q15: =I15-M15 -> 850
A16: =A14+7 -> 45690 | B16: 12 | C16: =IF(B16=0,"",B16/C$5) -> 0.85714286 | D16: 10275 | E16: =IFERROR(D16/B16,"") -> 856.25 | F16: 533 | G16: =IFERROR(F16/D16,"") -> 0.051873479
A17: =A16+7 -> 45697 | B17: 12 | C17: =IF(B17=0,"",B17/C$5) -> 0.85714286 | D17: 10275 | E17: =IFERROR(D17/B17,"") -> 856.25 | F17: 9625 | G17: =IFERROR(F17/D17,"") -> 0.93673966
A18: =A17+7 -> 45704 | B18: 12 | C18: =IF(B18=0,"",B18/C$5) -> 0.85714286 | D18: 10275 | E18: =IFERROR(D18/B18,"") -> 856.25 | F18: 9625 | G18: =IFERROR(F18/D18,"") -> 0.93673966
A19: =A18+7 -> 45711 | B19: 12 | C19: =IF(B19=0,"",B19/C$5) -> 0.85714286 | D19: 10275 | E19: =IFERROR(D19/B19,"") -> 856.25 | F19: 9689 | G19: =IFERROR(F19/D19,"") -> 0.94296837
A20: Monthly Target | B20: 12 | C20: =IF(B20=0,"",B20/C$5) -> 0.85714286 | D20: 10850 | E20: =D20/B20 -> 904.16667 | F20: 10850 | G20: =IFERROR(F20/D20,"") -> 1 | H20: 9789 | I20: 10850 | J20: =IF(H20=0,"",H20-I20) -> -1061 | K20: =IFERROR((H20-I20)/H20,"") -> -0.10838697 | L20: 9702 | M20: 10000 | N20: =IF(L20=0,"",L20-M20) -> -298 | O20: =IFERROR((L20-M20)/L20,"") -> -0.030715316 | P20: =H20-L20 -> 87 | Q20: =I20-M20 -> 850 | R20: $9,000 in building improvements not in expenses (1/2 year property taxes paid)
A21: =A19+7 -> 45718 | B21: 9 | C21: =IF(B21=0,"",B21/C$5) -> 0.64285714 | D21: 8650 | E21: =IFERROR(D21/B21,"") -> 961.11111 | F21: 5350 | G21: =IFERROR(F21/D21,"") -> 0.61849711
A22: =A21+7 -> 45725 | B22: 9 | C22: =IF(B22=0,"",B22/D$6) -> 0.5625 | D22: 8650 | E22: =IFERROR(D22/B22,"") -> 961.11111 | F22: 8650 | G22: =IFERROR(F22/D22,"") -> 1
A23: =A22+7 -> 45732 | B23: 13 | C23: =IF(B23=0,"",B23/D$6) -> 0.8125 | D23: 10835 | E23: =IFERROR(D23/B23,"") -> 833.46154 | F23: 9200 | G23: =IFERROR(F23/D23,"") -> 0.84910014
A24: =A23+7 -> 45739 | B24: 13 | C24: =IF(B24=0,"",B24/D$6) -> 0.8125 | D24: 10835 | E24: =IFERROR(D24/B24,"") -> 833.46154 | F24: 10442 | G24: =IFERROR(F24/D24,"") -> 0.96372866
A25: =A24+7 -> 45746 | B25: 13 | C25: =IF(B25=0,"",B25/D$6) -> 0.8125 | D25: 10835 | E25: =IFERROR(D25/B25,"") -> 833.46154 | F25: 10442 | G25: =IFERROR(F25/D25,"") -> 0.96372866
A26: Monthly Target | B26: 15 | C26: =IF(B26=0,"",B26/D$6) -> 0.9375 | D26: 10850 | E26: =D26/B26 -> 723.33333 | F26: 10850 | G26: =IFERROR(F26/D26,"") -> 1 | H26: 10442 | I26: 10850 | J26: =IF(H26=0,"",H26-I26) -> -408 | K26: =IFERROR((H26-I26)/H26,"") -> -0.039072975 | L26: 23891 | M26: 10000 | N26: =IF(L26=0,"",L26-M26) -> 13891 | O26: =IFERROR((L26-M26)/L26,"") -> 0.58143234 | P26: =H26-L26 -> -13449 | Q26: =I26-M26 -> 850 | R26: $15,000 Building Improvements Sweeneys
A27: =A25+7 -> 45753 | B27: 14 | C27: =IF(B27=0,"",B27/D$6) -> 0.875 | D27: 11600 | E27: =IFERROR(D27/B27,"") -> 828.57143 | F27: 11535 | G27: =IFERROR(F27/D27,"") -> 0.99439655
A28: =A27+7 -> 45760 | B28: 14 | C28: =IF(B28=0,"",B28/D$6) -> 0.875 | D28: 11600 | E28: =IFERROR(D28/B28,"") -> 828.57143 | F28: 11535 | G28: =IFERROR(F28/D28,"") -> 0.99439655
A29: =A28+7 -> 45767 | B29: 14 | C29: =IF(B29=0,"",B29/D$6) -> 0.875 | D29: 11600 | E29: =IFERROR(D29/B29,"") -> 828.57143 | F29: 11353 | G29: =IFERROR(F29/D29,"") -> 0.9787069
A30: =A29+7 -> 45774 | B30: 13 | C30: =IF(B30=0,"",B30/D$6) -> 0.8125 | D30: 10100 | E30: =IFERROR(D30/B30,"") -> 776.92308 | F30: 11535 | G30: =IFERROR(F30/D30,"") -> 1.1420792
A31: Monthly Target | B31: 12 | C31: =IF(B31=0,"",B31/C$5) -> 0.85714286 | D31: 10850 | E31: =D31/B31 -> 904.16667 | F31: 10850 | G31: =IFERROR(F31/D31,"") -> 1 | H31: 9955 | I31: 10850 | J31: =IF(H31=0,"",H31-I31) -> -895 | K31: =IFERROR((H31-I31)/H31,"") -> -0.089904571 | L31: 38751 | M31: 10000 | N31: =IF(L31=0,"",L31-M31) -> 28751 | O31: =IFERROR((L31-M31)/L31,"") -> 0.74194214 | P31: =H31-L31 -> -28796 | Q31: =I31-M31 -> 850
A32: =A30+7 -> 45781 | B32: 14 | C32: =IF(B32=0,"",B32/D$6) -> 0.875 | D32: 10885 | E32: =IFERROR(D32/B32,"") -> 777.5 | F32: 8335 | G32: =IFERROR(F32/D32,"") -> 0.76573266
A33: =A32+7 -> 45788 | B33: 15 | C33: =IF(B33=0,"",B33/D$6) -> 0.9375 | D33: 11735 | E33: =IFERROR(D33/B33,"") -> 782.33333 | F33: 11516 | G33: =IFERROR(F33/D33,"") -> 0.98133788
A34: =A33+7 -> 45795 | B34: 15 | C34: =IF(B34=0,"",B34/D$6) -> 0.9375 | D34: 11735 | E34: =IFERROR(D34/B34,"") -> 782.33333 | F34: 11516 | G34: =IFERROR(F34/D34,"") -> 0.98133788
A35: =A34+7 -> 45802 | B35: 15 | C35: =IF(B35=0,"",B35/D$6) -> 0.9375 | D35: 11735 | E35: =IFERROR(D35/B35,"") -> 782.33333 | F35: 12041 | G35: =IFERROR(F35/D35,"") -> 1.0260758
A36: Monthly Target | B36: 12 | C36: =IF(B36=0,"",B36/C$5) -> 0.85714286 | D36: 10850 | E36: =D36/B36 -> 904.16667 | F36: 10850 | G36: =IFERROR(F36/D36,"") -> 1 | H36: 15061 | I36: 10850 | J36: =IF(H36=0,"",H36-I36) -> 4211 | K36: =IFERROR((H36-I36)/H36,"") -> 0.27959631 | L36: 13324 | M36: 10000 | N36: =IF(L36=0,"",L36-M36) -> 3324 | O36: =IFERROR((L36-M36)/L36,"") -> 0.24947463 | P36: =H36-L36 -> 1737 | Q36: =I36-M36 -> 850 | R36: $4,000 in building improvments on Sweeneys
A37: =A35+7 -> 45809 | B37: 15 | C37: =IF(B37=0,"",B37/D$6) -> 0.9375 | D37: 11735 | E37: =IFERROR(D37/B37,"") -> 782.33333 | F37: 6189 | G37: =IFERROR(F37/D37,"") -> 0.52739668 | R37: 5
A38: =A37+7 -> 45816 | B38: 16 | C38: =IF(B38=0,"",B38/D$6) -> 1 | D38: 13775 | E38: =IFERROR(D38/B38,"") -> 860.9375 | F38: 12025 | G38: =IFERROR(F38/D38,"") -> 0.87295826
A39: =A38+7 -> 45823 | B39: 16 | C39: =IF(B39=0,"",B39/D$6) -> 1 | D39: 13775 | E39: =IFERROR(D39/B39,"") -> 860.9375 | F39: 12825 | G39: =IFERROR(F39/D39,"") -> 0.93103448
A40: =A39+7 -> 45830 | B40: 16 | C40: =IF(B40=0,"",B40/D$6) -> 1 | D40: 13775 | E40: =IFERROR(D40/B40,"") -> 860.9375 | F40: 12825 | G40: =IFERROR(F40/D40,"") -> 0.93103448
A41: =A40+7 -> 45837 | B41: 16 | C41: =IF(B41=0,"",B41/D$6) -> 1 | D41: 13775 | E41: =IFERROR(D41/B41,"") -> 860.9375 | F41: 12825 | G41: =IFERROR(F41/D41,"") -> 0.93103448
A42: Monthly Target | B42: 13 | C42: =IF(B42=0,"",B42/C$5) -> 0.92857143 | D42: 13850 | E42: =D42/B42 -> 1065.3846 | F42: 13850 | G42: =IFERROR(F42/D42,"") -> 1 | H42: 12500 | I42: 13850 | J42: =IF(H42=0,"",H42-I42) -> -1350 | K42: =IFERROR((H42-I42)/H42,"") -> -0.108 | L42: 21151 | M42: 12500 | N42: =IF(L42=0,"",L42-M42) -> 8651 | O42: =IFERROR((L42-M42)/L42,"") -> 0.40901139 | P42: =H42-L42 -> -8651 | Q42: =I42-M42 -> 1350 | R42: 18000 in building improvements mostly Sweeneys
A43: =A41+7 -> 45844 | B43: 15 | C43: =IF(B43=0,"",B43/D$6) -> 0.9375 | D43: 13050 | E43: =IFERROR(D43/B43,"") -> 870 | F43: 10550 | G43: =IFERROR(F43/D43,"") -> 0.80842912
...

Sheet ENPH
A1: KEY
A2: Manual Input
A3: Owner Input or Formula
A4: Formula | B4: ENPH
B5: # of Units | C5: 19 | D5: AO 4/1 | E5: 21 | F5: AO 4/20 | G5: 22 | I5: KPI Tracker
A10: Week Ending Sunday | B10: # of Occupied Units | C10: Occupancy % | D10: Total Leased Rent Amount $ | E10: Average Rent | F10: Total Collections to Date $ | G10: Collection Percentage | H10: Actual Revenue (Monthly Only) | I10: Budgeted Revenue (Monthly Only) | J10: Variance $ | K10: Variance % | L10: Actual Expense (Monthly Only) | M10: Budgeted Expense (Monthly Only | N10: Variance $ | O10: Variance % | P10: Net Income | Q10: Net Income Budgeted | R10: Notes:
A11: 45662 | B11: 18 | C11: =IF(B11=0,"",B11/C$5) -> 0.94736842 | D11: 17761 | E11: =IFERROR(D11/B11,"") -> 986.72222 | F11: 14359 | G11: =IFERROR(F11/D11,"") -> 0.80845673 | R11: 122 Harrison, 730 E Mulberry, 410 W Wheeling, 129 E Chestnut, 620 N Zane, 434 N Maple, 720 Hubert, 1215 N Columbus, 1401 W Mulberry (Garage)
A12: =A11+7 -> 45669 | B12: 18 | C12: =IF(B12=0,"",B12/C$5) -> 0.94736842 | D12: 17772 | E12: =IFERROR(D12/B12,"") -> 987.33333 | F12: 17761 | G12: =IFERROR(F12/D12,"") -> 0.99938105
A13: =A12+7 -> 45676 | B13: 18 | C13: =IF(B13=0,"",B13/C$5) -> 0.94736842 | D13: 18147 | E13: =IFERROR(D13/B13,"") -> 1008.1667 | F13: 17772 | G13: =IFERROR(F13/D13,"") -> 0.97933543
A14: =A13+7 -> 45683 | B14: 17 | C14: =IF(B14=0,"",B14/C$5) -> 0.89473684 | D14: 16947 | E14: =IFERROR(D14/B14,"") -> 996.88235 | F14: 17930 | G14: =IFERROR(F14/D14,"") -> 1.0580044
A15: Monthly Target | B15: 18 | C15: =IF(B15=0,"",B15/C$5) -> 0.94736842 | D15: 18850 | E15: =D15/B15 -> 1047.2222 | F15: 18850 | G15: =IFERROR(F15/D15,"") -> 1 | H15: 18824 | I15: 18850 | J15: =IF(H15=0,"",H15-I15) -> -26 | K15: =IFERROR((H15-I15)/H15,"") -> -0.0013812155 | L15: 22008 | M15: 17000 | N15: =IF(L15=0,"",L15-M15) -> 5008 | O15: =IFERROR((L15-M15)/L15,"") -> 0.22755362 | P15: =H15-L15 -> -3184 | Q15: =I15-M15 -> 1850 | R15: Property Tax payment for non escrowed properties
A16: =A14+7 -> 45690 | B16: 17 | C16: =IF(B16=0,"",B16/C$5) -> 0.89473684 | D16: 16947 | E16: =IFERROR(D16/B16,"") -> 996.88235 | F16: 8430 | G16: =IFERROR(F16/D16,"") -> 0.49743317
A17: =A16+7 -> 45697 | B17: 16 | C17: =IF(B17=0,"",B17/C$5) -> 0.84210526 | D17: 17036 | E17: =IFERROR(D17/B17,"") -> 1064.75 | F17: 14415 | G17: =IFERROR(F17/D17,"") -> 0.84614933
A18: =A17+7 -> 45704 | B18: 16 | C18: =IF(B18=0,"",B18/C$5) -> 0.84210526 | D18: 17036 | E18: =IFERROR(D18/B18,"") -> 1064.75 | F18: 15665 | G18: =IFERROR(F18/D18,"") -> 0.91952336
A19: =A18+7 -> 45711 | B19: 16 | C19: =IF(B19=0,"",B19/C$5) -> 0.84210526 | D19: 17036 | E19: =IFERROR(D19/B19,"") -> 1064.75 | F19: 16565 | G19: =IFERROR(F19/D19,"") -> 0.97235266
A20: Monthly Target | B20: 18 | C20: =IF(B20=0,"",B20/C$5) -> 0.94736842 | D20: 18850 | E20: =D20/B20 -> 1047.2222 | F20: 18850 | G20: =IFERROR(F20/D20,"") -> 1 | H20: 22822 | I20: 18850 | J20: =IF(H20=0,"",H20-I20) -> 3972 | K20: =IFERROR((H20-I20)/H20,"") -> 0.17404259 | L20: 19928 | M20: 17000 | N20: =IF(L20=0,"",L20-M20) -> 2928 | O20: =IFERROR((L20-M20)/L20,"") -> 0.14692894 | P20: =H20-L20 -> 2894 | Q20: =I20-M20 -> 1850 | R20: 1/2 year property taxes and $3700 in building improvements not included
A21: =A19+7 -> 45718 | B21: 18 | C21: =IF(B21=0,"",B21/C$5) -> 0.94736842 | D21: 19761 | E21: =IFERROR(D21/B21,"") -> 1097.8333 | F21: 7694 | G21: =IFERROR(F21/D21,"") -> 0.38935277
A22: =A21+7 -> 45725 | B22: 18 | C22: =IF(B22=0,"",B22/C$5) -> 0.94736842 | D22: 19761 | E22: =IFERROR(D22/B22,"") -> 1097.8333 | F22: 16850 | G22: =IFERROR(F22/D22,"") -> 0.85268964
A23: =A22+7 -> 45732 | B23: 18 | C23: =IF(B23=0,"",B23/C$5) -> 0.94736842 | D23: 19761 | E23: =IFERROR(D23/B23,"") -> 1097.8333 | F23: 16850 | G23: =IFERROR(F23/D23,"") -> 0.85268964
A24: =A23+7 -> 45739 | B24: 18 | C24: =IF(B24=0,"",B24/C$5) -> 0.94736842 | D24: 19761 | E24: =IFERROR(D24/B24,"") -> 1097.8333 | F24: 18168 | G24: =IFERROR(F24/D24,"") -> 0.91938667
A25: =A24+7 -> 45746 | B25: 18 | C25: =IF(B25=0,"",B25/C$5) -> 0.94736842 | D25: 19761 | E25: =IFERROR(D25/B25,"") -> 1097.8333 | F25: 18543 | G25: =IFERROR(F25/D25,"") -> 0.93836344
A26: Monthly Target | B26: 18 | C26: =IF(B26=0,"",B26/C$5) -> 0.94736842 | D26: 18850 | E26: =D26/B26 -> 1047.2222 | F26: 18850 | G26: =IFERROR(F26/D26,"") -> 1 | H26: 18543 | I26: 18850 | J26: =IF(H26=0,"",H26-I26) -> -307 | K26: =IFERROR((H26-I26)/H26,"") -> -0.016556113 | L26: 30094 | M26: 17000 | N26: =IF(L26=0,"",L26-M26) -> 13094 | O26: =IFERROR((L26-M26)/L26,"") -> 0.43510334 | P26: =H26-L26 -> -11551 | Q26: =I26-M26 -> 1850 | R26: $6,000 building improvements 1401 Mulberry and $2700 apraisal costs
A27: =A25+7 -> 45753 | B27: 21 | C27: =IF(B27=0,"",B27/E$5) -> 1 | D27: 22861 | E27: =IFERROR(D27/B27,"") -> 1088.619 | F27: 16025 | G27: =IFERROR(F27/D27,"") -> 0.70097546
A28: =A27+7 -> 45760 | B28: 21 | C28: =IF(B28=0,"",B28/E$5) -> 1 | D28: 22861 | E28: =IFERROR(D28/B28,"") -> 1088.619 | F28: 20275 | G28: =IFERROR(F28/D28,"") -> 0.88688159
A29: =A28+7 -> 45767 | B29: 22 | C29: =IF(B29=0,"",B29/G$5) -> 1 | D29: 23861 | E29: =IFERROR(D29/B29,"") -> 1084.5909 | F29: 20275 | G29: =IFERROR(F29/D29,"") -> 0.84971292
A30: =A29+7 -> 45774 | B30: 21 | C30: =IF(B30=0,"",B30/G$5) -> 0.95454545 | D30: 23811 | E30: =IFERROR(D30/B30,"") -> 1133.8571 | F30: 20563 | G30: =IFERROR(F30/D30,"") -> 0.86359246
A31: Monthly Target | B31: 18 | C31: =IF(B31=0,"",B31/C$5) -> 0.94736842 | D31: 18850 | E31: =D31/B31 -> 1047.2222 | F31: 18850 | G31: =IFERROR(F31/D31,"") -> 1 | H31: 17326 | I31: 18850 | J31: =IF(H31=0,"",H31-I31) -> -1524 | K31: =IFERROR((H31-I31)/H31,"") -> -0.087960291 | L31: 33533 | M31: 17000 | N31: =IF(L31=0,"",L31-M31) -> 16533 | O31: =IFERROR((L31-M31)/L31,"") -> 0.49303671 | P31: =H31-L31 -> -16207 | Q31: =I31-M31 -> 1850
A32: =A30+7 -> 45781 | B32: 19 | C32: =IF(B32=0,"",B32/G$5) -> 0.86363636 | D32: 21661 | E32: =IFERROR(D32/B32,"") -> 1140.0526 | F32: 12106 | G32: =IFERROR(F32/D32,"") -> 0.55888463
